<?xml version="1.0"?>
<sdf version="1.9">
  <model name="x500_base">
    <pose>0 0 0.24 0 0 0</pose>
    <self_collide>false</self_collide>
    <static>false</static>
    <link name="base_link">
      <pose>0 0 0 0 0 0</pose>
      <inertial>
          <pose>0 0 0 0 0 0</pose>
          <mass>2.0</mass>
          <inertia>
            <ixx>0.02166666666666667</ixx>
            <ixy>0</ixy>
            <ixz>0</ixz>
            <iyy>0.02166666666666667</iyy>
            <iyz>0</iyz>
            <izz>0.04000000000000001</izz>
          </inertia>
      </inertial>
      <gravity>true</gravity>
      <velocity_decay />
      <visual name="base_link_visual">
        <pose>0.2 0 -0.30 0 0 1.571</pose>
        <geometry>
          <mesh>
            <uri>model://dron/djimini4pro.obj</uri>
            <scale>2 2 2</scale>
          </mesh>
        </geometry>
      </visual> 
      <collision name="base_link_collision_0">
        <pose>0 0 -0.30 0 0 0</pose>
        <geometry>
          <box>
            <size>0.1 0.1 0.05</size>
          </box>
        </geometry>
        <surface>
          <contact>
            <ode>
              <min_depth>0.001</min_depth>
              <max_vel>0</max_vel>
            </ode>
          </contact>
          <friction>
            <ode />
          </friction>
        </surface>
      </collision>

      <sensor name="air_pressure_sensor" type="air_pressure">
        <!-- <gz_frame_id>base_link</gz_frame_id> -->
        <always_on>1</always_on>
        <update_rate>50</update_rate>
        <air_pressure>
          <pressure>
            <noise type="gaussian">
              <mean>0</mean>
              <stddev>3</stddev>
            </noise>
          </pressure>
        </air_pressure>
      </sensor>
      <sensor name="magnetometer_sensor" type="magnetometer">
        <!-- <gz_frame_id>base_link</gz_frame_id> -->
        <always_on>1</always_on>
        <update_rate>100</update_rate>
        <magnetometer>
          <!-- TODO: update to fix units and coordinate system when we move past Harmonic -->
          <!-- See https://github.com/gazebosim/gz-sim/pull/2460 -->
          <!-- 3mgauss RMS: NOTE: noise is in tesla but sensor reports data in gauss -->
          <!-- Noise modeled after IIS2MDC -->
          <x>
            <noise type="gaussian">
              <stddev>0.0001</stddev>
            </noise>
          </x>
          <y>
            <noise type="gaussian">
              <stddev>0.0001</stddev>
            </noise>
          </y>
          <z>
            <noise type="gaussian">
              <stddev>0.0001</stddev>
            </noise>
          </z>
        </magnetometer>
      </sensor>
      <sensor name="imu_sensor" type="imu">
        <!-- <gz_frame_id>base_link</gz_frame_id> -->
        <always_on>1</always_on>
        <update_rate>250</update_rate>
        <imu>
          <angular_velocity>
            <!-- Noise modeled after IIM42653 -->
            <!-- 0.05 deg/s converted to rad/s -->
            <x>
              <noise type="gaussian">
                <mean>0.0</mean>
                <stddev>0.0008726646</stddev>
              </noise>
            </x>
            <y>
              <noise type="gaussian">
                <mean>0.0</mean>
                <stddev>0.0008726646</stddev>
              </noise>
            </y>
            <z>
              <noise type="gaussian">
                <mean>0.0</mean>
                <stddev>0.0008726646</stddev>
              </noise>
            </z>
          </angular_velocity>
          <linear_acceleration>
            <!-- Noise modeled after IIM42653 -->
            <!-- X & Y axis: 0.65 mg-rms converted to m/ss -->
            <x>
              <noise type="gaussian">
                <mean>0.0</mean>
                <stddev>0.00637</stddev>
              </noise>
            </x>
            <y>
              <noise type="gaussian">
                <mean>0.0</mean>
                <stddev>0.00637</stddev>
              </noise>
            </y>
            <!-- Z axis: 0.70 mg-rms converted to m/ss-->
            <z>
              <noise type="gaussian">
                <mean>0.0</mean>
                <stddev>0.00686</stddev>
              </noise>
            </z>
          </linear_acceleration>
        </imu>
      </sensor>
      <sensor name="navsat_sensor" type="navsat">
        <!-- <gz_frame_id>base_link</gz_frame_id> -->
        <always_on>1</always_on>
        <update_rate>30</update_rate>
      </sensor>
    </link>

    <link name="rotor_0"> 
      <gravity>true</gravity>
      <self_collide>false</self_collide>
      <velocity_decay />
      <pose> 0.174 -0.174 0.06 0 0 0</pose>
      <inertial>
        <mass>0.016076923076923075</mass>
        <inertia>
          <ixx>3.8464910483993325e-07</ixx>
          <iyy>2.6115851691700804e-05</iyy>
          <izz>2.649858234714004e-05</izz>
        </inertia>
      </inertial>
      <visual name="rotor_0_visual">
        <pose>-0.174 -0.0415 -0.362 0 0 0</pose>
        <geometry>
          <mesh>
            <uri>model://dron/propela.obj</uri>
            <scale>2 2 2</scale>
          </mesh>
        </geometry>
      </visual>
    </link>
    <joint name="rotor_0_joint" type="revolute">
      <parent>base_link</parent>
      <child>rotor_0</child>
      <axis>
        <xyz>0 0 1</xyz>
        <limit>
          <lower>-1e+16</lower>
          <upper>1e16</upper>
        </limit>
        <dynamics>
          <spring_reference>0</spring_reference>
          <spring_stiffness>0</spring_stiffness>
        </dynamics>
      </axis>
    </joint>

    <link name="rotor_1"> 
      <gravity>true</gravity>
      <self_collide>false</self_collide>
      <velocity_decay />
      <pose> -0.174 0.174 0.06 0 0 0</pose>
      <inertial>
        <mass>0.016076923076923075</mass>
        <inertia>
          <ixx>3.8464910483993325e-07</ixx>
          <iyy>2.6115851691700804e-05</iyy>
          <izz>2.649858234714004e-05</izz>
        </inertia>
      </inertial>
      <visual name="rotor_1_visual">
        <pose>-0.135 -0.0769 -0.4 0 0 0</pose>
        <geometry>
          <mesh>
            <uri>model://dron/propela.obj</uri>
            <scale>2 2 2</scale>
          </mesh>
        </geometry>
      </visual>
    </link>
    <joint name="rotor_1_joint" type="revolute">
      <parent>base_link</parent>
      <child>rotor_1</child>
      <axis>
        <xyz>0 0 1</xyz>
        <limit>
          <lower>-1e+16</lower>
          <upper>1e16</upper>
        </limit>
        <dynamics>
          <spring_reference>0</spring_reference>
          <spring_stiffness>0</spring_stiffness>
        </dynamics>
      </axis>
    </joint>

    <link name="rotor_2"> 
      <gravity>true</gravity>
      <self_collide>false</self_collide>
      <velocity_decay />
      <pose> 0.174 0.174 0.06 0 0 0</pose>
      <inertial>
        <mass>0.016076923076923075</mass>
        <inertia>
          <ixx>3.8464910483993325e-07</ixx>
          <iyy>2.6115851691700804e-05</iyy>
          <izz>2.649858234714004e-05</izz>
        </inertia>
      </inertial>
      <visual name="rotor_2_visual">
        <pose>-0.174 -0.0769 -0.362 0 0 0</pose>
        <geometry>
          <mesh>
            <uri>model://dron/propela.obj</uri>
            <scale>2 2 2</scale>
          </mesh>
        </geometry>
      </visual>
    </link>
    <joint name="rotor_2_joint" type="revolute">
      <parent>base_link</parent>
      <child>rotor_2</child>
      <axis>
        <xyz>0 0 1</xyz>
        <limit>
          <lower>-1e+16</lower>
          <upper>1e16</upper>
        </limit>
        <dynamics>
          <spring_reference>0</spring_reference>
          <spring_stiffness>0</spring_stiffness>
        </dynamics>
      </axis>
    </joint>

    <link name="rotor_3"> 
      <gravity>true</gravity>
      <self_collide>false</self_collide>
      <velocity_decay />
      <pose> -0.174 -0.174 0.06 0 0 0</pose>
      <inertial>
        <mass>0.016076923076923075</mass>
        <inertia>
          <ixx>3.8464910483993325e-07</ixx>
          <iyy>2.6115851691700804e-05</iyy>
          <izz>2.649858234714004e-05</izz>
        </inertia>
      </inertial>
      <visual name="rotor_3_visual">
        <pose>-0.135 -0.0443 -0.4 0 0 0</pose>
        <geometry>
          <mesh>
            <uri>model://dron/propela.obj</uri>
            <scale>2 2 2</scale>
          </mesh>
        </geometry>
      </visual>
    </link>
    <joint name="rotor_3_joint" type="revolute">
      <parent>base_link</parent>
      <child>rotor_3</child>
      <axis>
        <xyz>0 0 1</xyz>
        <limit>
          <lower>-1e+16</lower>
          <upper>1e16</upper>
        </limit>
        <dynamics>
          <spring_reference>0</spring_reference>
          <spring_stiffness>0</spring_stiffness>
        </dynamics>
      </axis>
    </joint>

    <link name="camera_main_link">
      <pose>0.18 0 -0.28 0 0 0</pose>
      <visual name="marker_main">
        <geometry>
          <box>
            <size>0.05 0.05 0.05</size> </box>
        </geometry>
        <material>
          <ambient>1 0 0 1</ambient> <diffuse>1 0 0 1</diffuse>
        </material>
      </visual>
      <inertial>
        <mass>0.0001</mass>
        <inertia>
          <ixx>0.00000001</ixx>
          <iyy>0.00000001</iyy>
          <izz>0.00000001</izz>
        </inertia>
      </inertial>
      <sensor name="camera_main" type="camera">
        <always_on>1</always_on>
        <update_rate>30</update_rate>
        <visualize>true</visualize>
        <topic>camera_main</topic> <camera>
          <horizontal_fov>1.396</horizontal_fov> <image>
            <width>1920</width>
            <height>1080</height>
            <format>R8G8B8</format>
          </image>
          <clip>
            <near>0.1</near>
            <far>100</far>
          </clip>
        </camera>
      </sensor>
    </link>

    <joint name="camera_main_joint" type="fixed">
      <parent>base_link</parent>
      <child>camera_main_link</child>
    </joint>

    <link name="camera_side_link">
      <pose>0.2 0.15 -0.02 0 0 -1.57</pose> 
      <!-- <visual name="marker_side">
        <geometry>
          <sphere>
            <radius>0.03</radius> </sphere>
        </geometry>
        <material>
          <ambient>0 1 0 1</ambient> <diffuse>0 1 0 1</diffuse>
        </material>
      </visual> -->
      <inertial>
        <mass>0.0001</mass>
        <inertia>
          <ixx>0.00000001</ixx>
          <iyy>0.00000001</iyy>
          <izz>0.00000001</izz>
        </inertia>
      </inertial>
      <sensor name="camera_side" type="camera">
        <always_on>1</always_on>
        <update_rate>20</update_rate>
        <visualize>true</visualize>
        <topic>camera_side</topic>
        <camera>
          <horizontal_fov>2.0</horizontal_fov> <image>
            <width>640</width>
            <height>480</height>
            <format>R8G8B8</format>
          </image>
        </camera>
      </sensor>
    </link>

    <joint name="camera_side_joint" type="fixed">
      <parent>base_link</parent>
      <child>camera_side_link</child>
    </joint>
  </model>
</sdf>